<?xml version="1.0" encoding="utf-8"?>
<!-- This URDF was automatically created by SolidWorks to URDF Exporter! Originally created by Stephen Brawner (brawner@gmail.com) 
     Commit Version: 1.6.0-4-g7f85cfe  Build Version: 1.6.7995.38578
     For more information, please see http://wiki.ros.org/sw_urdf_exporter -->
<robot
  name="amiga_base">
  <link
    name="base_link">
    <inertial>
      <origin
        xyz="-0.00388540361851519 -0.0114840118573206 -0.0930212802383114"
        rpy="0 0 0" />
      <mass
        value="25.8523651994522" />
      <inertia
        ixx="2.63966251365881"
        ixy="-0.000921389215545839"
        ixz="-0.000202110779806177"
        iyy="1.67612712696995"
        iyz="3.4282007112781E-06"
        izz="4.04844807092914" />
    </inertial>
    <visual>
      <origin
        xyz="0 0 0"
        rpy="0 0 0" />
      <geometry>
        <mesh
          filename="package://amiga_ros2_description/meshes/base_link.STL" />
      </geometry>
      <material
        name="">
        <color
          rgba="0.752941176470588 0.752941176470588 0.752941176470588 1" />
      </material>
    </visual>
    <collision>
      <origin
        xyz="0 0 0"
        rpy="0 0 0" />
      <geometry>
        <mesh
          filename="package://amiga_ros2_description/meshes/base_link.STL" />
      </geometry>
    </collision>
  </link>
  <link
    name="front_right_wheel_link">
    <inertial>
      <origin
        xyz="-4.4917E-07 -0.00049736 2.7989E-06"
        rpy="0 0 0" />
      <mass
        value="7.4596" />
      <inertia
        ixx="0.075753"
        ixy="-7.6479E-08"
        ixz="-8.201E-07"
        iyy="0.13767"
        iyz="3.0486E-08"
        izz="0.075755" />
    </inertial>
    <visual>
      <origin
        xyz="0 0 0"
        rpy="0 0 0" />
      <geometry>
        <mesh
          filename="package://amiga_ros2_description/meshes/front_right_wheel_link.STL" />
      </geometry>
      <material
        name="">
        <color
          rgba="0.79216 0.81961 0.93333 1" />
      </material>
    </visual>
    <collision>
      <origin
        xyz="0 0 0"
        rpy="0 0 0" />
      <geometry>
        <mesh
          filename="package://amiga_ros2_description/meshes/front_right_wheel_link.STL" />
      </geometry>
    </collision>
  </link>
  <joint
    name="front_right_wheel_joint"
    type="continuous">
    <origin
      xyz="0.352875765322685 -0.562186930189418 -0.43410291085732"
      rpy="0 0 0" />
    <parent
      link="base_link" />
    <child
      link="front_right_wheel_link" />
    <axis
      xyz="0 -1 0" />
  </joint>
  <link
    name="front_left_wheel_link">
    <inertial>
      <origin
        xyz="-7.61597559462146E-07 0.000497356255064363 -2.74313059063502E-06"
        rpy="0 0 0" />
      <mass
        value="7.45957276647556" />
      <inertia
        ixx="0.0757532932653025"
        ixy="7.41655465830861E-08"
        ixz="9.02980440719608E-07"
        iyy="0.137673473884529"
        iyz="3.6160666130332E-08"
        izz="0.0757549794144104" />
    </inertial>
    <visual>
      <origin
        xyz="0 0 0"
        rpy="0 0 0" />
      <geometry>
        <mesh
          filename="package://amiga_ros2_description/meshes/front_left_wheel_link.STL" />
      </geometry>
      <material
        name="">
        <color
          rgba="0.792156862745098 0.819607843137255 0.933333333333333 1" />
      </material>
    </visual>
    <collision>
      <origin
        xyz="0 0 0"
        rpy="0 0 0" />
      <geometry>
        <mesh
          filename="package://amiga_ros2_description/meshes/front_left_wheel_link.STL" />
      </geometry>
    </collision>
  </link>
  <joint
    name="front_left_wheel_joint"
    type="continuous">
    <origin
      xyz="0.30508 0.56219 -0.4341"
      rpy="0 0 0" />
    <parent
      link="base_link" />
    <child
      link="front_left_wheel_link" />
    <axis
      xyz="0 1 0" />
  </joint>
  <link
    name="rear_right_wheel_link">
    <inertial>
      <origin
        xyz="-2.74660993282438E-06 -0.000497357324648728 -7.35732217954643E-07"
        rpy="0 0 0" />
      <mass
        value="7.45957260699585" />
      <inertia
        ixx="0.0757549867797192"
        ixy="-3.60956246170686E-08"
        ixz="8.9587753431613E-07"
        iyy="0.137673473677867"
        iyz="-7.42765420879559E-08"
        izz="0.0757532856367096" />
    </inertial>
    <visual>
      <origin
        xyz="0 0 0"
        rpy="0 0 0" />
      <geometry>
        <mesh
          filename="package://amiga_ros2_description/meshes/rear_right_wheel_link.STL" />
      </geometry>
      <material
        name="">
        <color
          rgba="0.792156862745098 0.819607843137255 0.933333333333333 1" />
      </material>
    </visual>
    <collision>
      <origin
        xyz="0 0 0"
        rpy="0 0 0" />
      <geometry>
        <mesh
          filename="package://amiga_ros2_description/meshes/rear_right_wheel_link.STL" />
      </geometry>
    </collision>
  </link>
  <joint
    name="rear_right_wheel_joint"
    type="continuous">
    <origin
      xyz="-0.30507 -0.56219 -0.4341"
      rpy="0 0 0" />
    <parent
      link="base_link" />
    <child
      link="rear_right_wheel_link" />
    <axis
      xyz="0 -1 0" />
  </joint>
  <link
    name="rear_left_wheel_link">
    <inertial>
      <origin
        xyz="2.73333040090584E-06 0.000497370817003275 5.78761871816713E-07"
        rpy="0 0 0" />
      <mass
        value="7.45957431743695" />
      <inertia
        ixx="0.0757552431884799"
        ixy="-1.70085074043754E-08"
        ixz="-4.19890051625004E-07"
        iyy="0.137673684199435"
        iyz="5.3518158632754E-08"
        izz="0.0757531934363969" />
    </inertial>
    <visual>
      <origin
        xyz="0 0 0"
        rpy="0 0 0" />
      <geometry>
        <mesh
          filename="package://amiga_ros2_description/meshes/rear_left_wheel_link.STL" />
      </geometry>
      <material
        name="">
        <color
          rgba="0.792156862745098 0.819607843137255 0.933333333333333 1" />
      </material>
    </visual>
    <collision>
      <origin
        xyz="0 0 0"
        rpy="0 0 0" />
      <geometry>
        <mesh
          filename="package://amiga_ros2_description/meshes/rear_left_wheel_link.STL" />
      </geometry>
    </collision>
  </link>
  <joint
    name="rear_left_wheel_joint"
    type="continuous">
    <origin
      xyz="-0.35312 0.56219 -0.43414"
      rpy="0 0 0" />
    <parent
      link="base_link" />
    <child
      link="rear_left_wheel_link" />
    <axis
      xyz="0 1 0" />
  </joint>
  <link
    name="front_camera_link">
    <inertial>
      <origin
        xyz="-0.012571 0.00044923 0.0034003"
        rpy="0 0 0" />
      <mass
        value="0.044671" />
      <inertia
        ixx="5.7791E-05"
        ixy="-2.1834E-07"
        ixz="-3.5985E-07"
        iyy="8.2105E-06"
        iyz="1.217E-08"
        izz="5.2365E-05" />
    </inertial>
    <visual>
      <origin
        xyz="0 0 0"
        rpy="0 0 0" />
      <geometry>
        <mesh
          filename="package://amiga_ros2_description/meshes/front_camera_link.STL" />
      </geometry>
      <material
        name="">
        <color
          rgba="0.75294 0.75294 0.75294 1" />
      </material>
    </visual>
    <collision>
      <origin
        xyz="0 0 0"
        rpy="0 0 0" />
      <geometry>
        <mesh
          filename="package://amiga_ros2_description/meshes/front_camera_link.STL" />
      </geometry>
    </collision>
  </link>
  <joint
    name="front_camera_joint"
    type="fixed">
    <origin
      xyz="-0.24762 0.27301 0.94634"
      rpy="3.1416 0.2618 0" />
    <parent
      link="base_link" />
    <child
      link="front_camera_link" />
    <axis
      xyz="0 0 0" />
  </joint>
  <link
    name="back_camera_link">
    <inertial>
      <origin
        xyz="-0.0125711047202639 0.000449227195306823 0.00340033694707764"
        rpy="0 0 0" />
      <mass
        value="0.0446713874668939" />
      <inertia
        ixx="5.77911845580861E-05"
        ixy="-2.18340360390322E-07"
        ixz="-3.59854627945512E-07"
        iyy="8.21049664173375E-06"
        iyz="1.21698272010123E-08"
        izz="5.23654033150741E-05" />
    </inertial>
    <visual>
      <origin
        xyz="0 0 0"
        rpy="0 0 0" />
      <geometry>
        <mesh
          filename="package://amiga_ros2_description/meshes/back_camera_link.STL" />
      </geometry>
      <material
        name="">
        <color
          rgba="0.752941176470588 0.752941176470588 0.752941176470588 1" />
      </material>
    </visual>
    <collision>
      <origin
        xyz="0 0 0"
        rpy="0 0 0" />
      <geometry>
        <mesh
          filename="package://amiga_ros2_description/meshes/back_camera_link.STL" />
      </geometry>
    </collision>
  </link>
  <joint
    name="back_camera_joint"
    type="fixed">
    <origin
      xyz="-0.43838 0.27301 0.94634"
      rpy="-3.1416 0.2618 -3.1416" />
    <parent
      link="base_link" />
    <child
      link="back_camera_link" />
    <axis
      xyz="0 0 0" />
  </joint>
  <link
    name="GPS_link">
    <inertial>
      <origin
        xyz="-0.0218600950360632 0.0419855291223912 -0.439360640018416"
        rpy="0 0 0" />
      <mass
        value="3.90964932592591" />
      <inertia
        ixx="0.0499433743737193"
        ixy="-8.16619228498416E-05"
        ixz="-0.00187187931620271"
        iyy="0.0445451188688448"
        iyz="-0.000101175088384219"
        izz="0.0121756087074613" />
    </inertial>
    <visual>
      <origin
        xyz="0 0 0"
        rpy="0 0 0" />
      <geometry>
        <mesh
          filename="package://amiga_ros2_description/meshes/GPS_link.STL" />
      </geometry>
      <material
        name="">
        <color
          rgba="0.0980392156862745 0.0980392156862745 0.0980392156862745 1" />
      </material>
    </visual>
    <collision>
      <origin
        xyz="0 0 0"
        rpy="0 0 0" />
      <geometry>
        <mesh
          filename="package://amiga_ros2_description/meshes/GPS_link.STL" />
      </geometry>
    </collision>
  </link>
  <joint
    name="GPS_joint"
    type="fixed">
    <origin
      xyz="-0.343 0.27301 1.0163"
      rpy="0 0 0" />
    <parent
      link="base_link" />
    <child
      link="GPS_link" />
    <axis
      xyz="0 0 0" />
  </joint>
  <link
    name="front_imu_link">
    <inertial>
      <origin
        xyz="0.0008598 0.039549 0.012111"
        rpy="0 0 0" />
      <mass
        value="0.044671" />
      <inertia
        ixx="5.7791E-05"
        ixy="2.1834E-07"
        ixz="3.5985E-07"
        iyy="8.2105E-06"
        iyz="1.217E-08"
        izz="5.2365E-05" />
    </inertial>
    <visual>
      <origin
        xyz="0 0 0"
        rpy="0 0 0" />
      <geometry>
        <mesh
          filename="package://amiga_ros2_description/meshes/front_imu_link.STL" />
      </geometry>
      <material
        name="">
        <color
          rgba="0.75294 0.75294 0.75294 1" />
      </material>
    </visual>
    <collision>
      <origin
        xyz="0 0 0"
        rpy="0 0 0" />
      <geometry>
        <mesh
          filename="package://amiga_ros2_description/meshes/front_imu_link.STL" />
      </geometry>
    </collision>
  </link>
  <joint
    name="front_imu_joint"
    type="fixed">
    <origin
      xyz="-0.2646 0.23301 0.93483"
      rpy="0 0.2618 0" />
    <parent
      link="base_link" />
    <child
      link="front_imu_link" />
    <axis
      xyz="0 0 0" />
  </joint>
  <link
    name="back_imu_link">
    <inertial>
      <origin
        xyz="0 0 0"
        rpy="0 0 0" />
      <mass
        value="0" />
      <inertia
        ixx="0"
        ixy="0"
        ixz="0"
        iyy="0"
        iyz="0"
        izz="0" />
    </inertial>
    <visual>
      <origin
        xyz="0 0 0"
        rpy="0 0 0" />
      <geometry>
        <mesh
          filename="package://amiga_ros2_description/meshes/back_imu_link.STL" />
      </geometry>
      <material
        name="">
        <color
          rgba="1 1 1 1" />
      </material>
    </visual>
    <collision>
      <origin
        xyz="0 0 0"
        rpy="0 0 0" />
      <geometry>
        <mesh
          filename="package://amiga_ros2_description/meshes/back_imu_link.STL" />
      </geometry>
    </collision>
  </link>
  <joint
    name="back_imu_joint"
    type="fixed">
    <origin
      xyz="-0.4214 0.313 0.93483"
      rpy="0 0.2618 -3.1416" />
    <parent
      link="base_link" />
    <child
      link="back_imu_link" />
    <axis
      xyz="0 0 0" />
  </joint>
</robot>